<?xml version="1.0" ?>
<!--
  Demo world with a widget displaying images coming from a depth camera sensor.
-->
<sdf version="1.6">
  <world name="rover_experiment">
    <physics name="1ms" type="ignored">
      <max_step_size>0.001</max_step_size>
      <real_time_factor>1.0</real_time_factor>
    </physics>
    <plugin
      filename="ignition-gazebo-physics-system"
      name="gz::sim::systems::Physics">
    </plugin>
    <plugin
      filename="ignition-gazebo-sensors-system"
      name="gz::sim::systems::Sensors">
      <render_engine>ogre2</render_engine>
    </plugin>
    <plugin filename="ignition-gazebo-imu-system"
            name="ignition::gazebo::systems::Imu">
    </plugin>
    <plugin
      filename="ignition-gazebo-scene-broadcaster-system"
      name="gz::sim::systems::SceneBroadcaster">
    </plugin>

    <gui fullscreen="0">

      <!-- 3D scene -->
      <plugin filename="MinimalScene" name="3D View">
        <ignition-gui>
          <title>3D View</title>
          <property type="bool" key="showTitleBar">false</property>
          <property type="string" key="state">docked</property>
        </ignition-gui>

        <engine>ogre2</engine>
        <scene>scene</scene>
        <ambient_light>0.4 0.4 0.4</ambient_light>
        <background_color>0.8 0.8 0.8</background_color>
        <camera_pose>-6 0 6 0 0.5 0</camera_pose>
      </plugin>

      <!-- Plugins that add functionality to the scene -->
      <plugin filename="EntityContextMenuPlugin" name="Entity context menu">
        <ignition-gui>
          <property key="state" type="string">floating</property>
          <property key="width" type="double">5</property>
          <property key="height" type="double">5</property>
          <property key="showTitleBar" type="bool">false</property>
        </ignition-gui>
      </plugin>
      <plugin filename="GzSceneManager" name="Scene Manager">
        <ignition-gui>
          <property key="resizable" type="bool">false</property>
          <property key="width" type="double">5</property>
          <property key="height" type="double">5</property>
          <property key="state" type="string">floating</property>
          <property key="showTitleBar" type="bool">false</property>
        </ignition-gui>
      </plugin>
      <plugin filename="InteractiveViewControl" name="Interactive view control">
        <ignition-gui>
          <property key="resizable" type="bool">false</property>
          <property key="width" type="double">5</property>
          <property key="height" type="double">5</property>
          <property key="state" type="string">floating</property>
          <property key="showTitleBar" type="bool">false</property>
        </ignition-gui>
      </plugin>
      <plugin filename="CameraTracking" name="Camera Tracking">
        <ignition-gui>
          <property key="resizable" type="bool">false</property>
          <property key="width" type="double">5</property>
          <property key="height" type="double">5</property>
          <property key="state" type="string">floating</property>
          <property key="showTitleBar" type="bool">false</property>
        </ignition-gui>
      </plugin>

      <plugin filename="ImageDisplay" name="Image Display">
        <ignition-gui>
          <property key="state" type="string">docked</property>
        </ignition-gui>
      </plugin>
    </gui>

    <light type="directional" name="sun">
      <cast_shadows>true</cast_shadows>
      <pose>0 0 10 0 0 0</pose>
      <diffuse>0.8 0.8 0.8 1</diffuse>
      <specular>0.2 0.2 0.2 1</specular>
      <attenuation>
        <range>1000</range>
        <constant>0.9</constant>
        <linear>0.01</linear>
        <quadratic>0.001</quadratic>
      </attenuation>
      <direction>-0.5 0.1 -0.9</direction>
    </light>

    <model name="ground_plane">
      <static>true</static>
      <link name="link">
        <collision name="collision">
          <geometry>
            <!--plane>
              <normal>0 0 1</normal>
              <size>100 100</size>
            </plane-->
            <box>
              <size>20 20 0.1</size>
            </box>
          </geometry>
        </collision>
        <visual name="visual">
          <geometry>
            <!--plane>
              <normal>0 0 1</normal>
              <size>100 100</size>
            </plane-->
            <box>
              <size>20 20 0.1</size>
            </box>
          </geometry>
          <material>
            <ambient>0.8 0.8 0.8 1</ambient>
            <diffuse>0.8 0.8 0.8 1</diffuse>
            <specular>0.8 0.8 0.8 1</specular>
          </material>
        </visual>
      </link>
    </model>

    <model name="box">
      <pose>0 -1 0.5 0 0 0</pose>
      <link name="box_link">
        <inertial>
          <inertia>
            <ixx>1</ixx>
            <ixy>0</ixy>
            <ixz>0</ixz>
            <iyy>1</iyy>
            <iyz>0</iyz>
            <izz>1</izz>
          </inertia>
          <mass>1.0</mass>
        </inertial>
        <collision name="box_collision">
          <geometry>
            <box>
              <size>1 1 1</size>
            </box>
          </geometry>
        </collision>

        <visual name="box_visual">
          <geometry>
            <box>
              <size>1 1 1</size>
            </box>
          </geometry>
          <material>
            <ambient>1 0 0 1</ambient>
            <diffuse>1 0 0 1</diffuse>
            <specular>1 0 0 1</specular>
          </material>
        </visual>
      </link>
    </model>
    <model name='vehicle_blue' canonical_link='chassis'>
      <pose relative_to='world'>0 0 1 0 0 0</pose>   <!--the pose is relative to the world by default-->

      <frame name="lidar_frame" attached_to='chassis'>
        <pose>0.8 0 0.5 0 0 0</pose>
      </frame>

      <link name='chassis'>
        <pose relative_to='__model__'>0.5 0 0.4 0 0 0</pose>
        <inertial> <!--inertial properties of the link mass, inertia matix-->
          <mass>1.14395</mass>
          <inertia>
            <ixx>0.126164</ixx>
            <ixy>0</ixy>
            <ixz>0</ixz>
            <iyy>0.416519</iyy>
            <iyz>0</iyz>
            <izz>0.481014</izz>
          </inertia>
        </inertial>
        <visual name='visual'>
          <geometry>
            <box>
              <size>2.0 1.0 0.5</size> <!--question: this size is in meter-->
            </box>
          </geometry>
          <!--let's add color to our link-->
          <material>
            <ambient>0.0 0.0 1.0 1</ambient>
            <diffuse>0.0 0.0 1.0 1</diffuse>
            <specular>0.0 0.0 1.0 1</specular>
          </material>
        </visual>
        <collision name='collision'> <!--todo: describe why we need the collision-->
          <geometry>
            <box>
              <size>2.0 1.0 0.5</size>
            </box>
          </geometry>
        </collision>
        <sensor name="imu_sensor" type="imu">
          <always_on>1</always_on>
          <update_rate>1</update_rate>
          <visualize>true</visualize>
          <topic>imu</topic>
        </sensor>
        <sensor name='gpu_lidar' type='gpu_lidar'>
          <pose relative_to='lidar_frame'>0 0 0 0 0 0</pose>
          <topic>lidar</topic>
          <update_rate>10</update_rate>
          <ray>
            <scan>
              <horizontal>
                <samples>640</samples>
                <resolution>1</resolution>
                <min_angle>-0.785398</min_angle>  <!-- -π/4 radians -->
                <max_angle>0.785398</max_angle>   <!-- π/4 radians -->
              </horizontal>
              <vertical>
                <samples>480</samples>
                <resolution>1</resolution>
                <min_angle>-0.549778</min_angle>  <!-- -1.099557/2 radians -->
                <max_angle>0.549778</max_angle>   <!-- 1.099557/2 radians -->
              </vertical>
            </scan>
            <range>
              <min>0.08</min>
              <max>10.0</max>
              <resolution>0.01</resolution>
            </range>
          </ray>
          <alwaysOn>1</alwaysOn>
          <visualize>true</visualize>
        </sensor>
      </link>
      <!--let's build the left wheel-->
      <link name='left_wheel'>
        <pose relative_to="chassis">-0.5 0.6 0 -1.5707 0 0</pose> <!--angles are in radian-->
        <inertial>
          <mass>2</mass>
          <inertia>
            <ixx>0.145833</ixx>
            <ixy>0</ixy>
            <ixz>0</ixz>
            <iyy>0.145833</iyy>
            <iyz>0</iyz>
            <izz>0.125</izz>
          </inertia>
        </inertial>
        <visual name='visual'>
          <geometry>
            <cylinder>
              <radius>0.4</radius>
              <length>0.2</length>
            </cylinder>
          </geometry>
          <material>
            <ambient>1.0 0.0 0.0 1</ambient>
            <diffuse>1.0 0.0 0.0 1</diffuse>
            <specular>1.0 0.0 0.0 1</specular>
          </material>
        </visual>
        <collision name='collision'>
          <geometry>
            <cylinder>
              <radius>0.4</radius>
              <length>0.2</length>
            </cylinder>
          </geometry>
        </collision>
      </link>

      <!--copy and paste for right wheel but change position-->
      <link name='right_wheel'>
        <pose relative_to="chassis">-0.5 -0.6 0 -1.5707 0 0</pose> <!--angles are in radian-->
        <inertial>
          <mass>1</mass>
          <inertia>
            <ixx>0.145833</ixx>
            <ixy>0</ixy>
            <ixz>0</ixz>
            <iyy>0.145833</iyy>
            <iyz>0</iyz>
            <izz>0.125</izz>
          </inertia>
        </inertial>
        <visual name='visual'>
          <geometry>
            <cylinder>
              <radius>0.4</radius>
              <length>0.2</length>
            </cylinder>
          </geometry>
          <material>
            <ambient>1.0 0.0 0.0 1</ambient>
            <diffuse>1.0 0.0 0.0 1</diffuse>
            <specular>1.0 0.0 0.0 1</specular>
          </material>
        </visual>
        <collision name='collision'>
          <geometry>
            <cylinder>
              <radius>0.4</radius>
              <length>0.2</length>
            </cylinder>
          </geometry>
        </collision>
      </link>

      <frame name="caster_frame" attached_to='chassis'>
        <pose>0.8 0 -0.2 0 0 0</pose>
      </frame>

      <!--caster wheel-->
      <link name='caster'>
        <pose relative_to='caster_frame'/>
        <inertial>
          <mass>1</mass>
          <inertia>
            <ixx>0.1</ixx>
            <ixy>0</ixy>
            <ixz>0</ixz>
            <iyy>0.1</iyy>
            <iyz>0</iyz>
            <izz>0.1</izz>
          </inertia>
        </inertial>
        <visual name='visual'>
          <geometry>
            <sphere>
              <radius>0.2</radius>
            </sphere>
          </geometry>
          <material>
            <ambient>0.0 1 0.0 1</ambient>
            <diffuse>0.0 1 0.0 1</diffuse>
            <specular>0.0 1 0.0 1</specular>
          </material>
        </visual>
        <collision name='collision'>
          <geometry>
            <sphere>
              <radius>0.2</radius>
            </sphere>
          </geometry>
        </collision>
      </link>

      <!--connecting these links together using joints-->
      <joint name='left_wheel_joint' type='revolute'> <!--continous joint is not supported yet-->
        <pose relative_to='left_wheel'/>
        <parent>chassis</parent>
        <child>left_wheel</child>
        <axis>
          <xyz expressed_in='__model__'>0 1 0</xyz> <!--can be descired to any frame or even arbitrary frames-->
          <limit>
            <lower>-1.79769e+308</lower>    <!--negative infinity-->
            <upper>1.79769e+308</upper>     <!--positive infinity-->
          </limit>
        </axis>
      </joint>

      <joint name='right_wheel_joint' type='revolute'>
        <pose relative_to='right_wheel'/>
        <parent>chassis</parent>
        <child>right_wheel</child>
        <axis>
          <xyz expressed_in='__model__'>0 1 0</xyz>
          <limit>
            <lower>-1.79769e+308</lower>    <!--negative infinity-->
            <upper>1.79769e+308</upper>     <!--positive infinity-->
          </limit>
        </axis>
      </joint>

      <!--different type of joints ball joint--> <!--defult value is the child-->
      <joint name='caster_wheel' type='ball'>
        <parent>chassis</parent>
        <child>caster</child>
      </joint>

      <!--diff drive plugin-->
      <plugin
          filename="ignition-gazebo-diff-drive-system"
          name="ignition::gazebo::systems::DiffDrive">
        <left_joint>left_wheel_joint</left_joint>
        <right_joint>right_wheel_joint</right_joint>
        <wheel_separation>1.2</wheel_separation>
        <wheel_radius>0.4</wheel_radius>
        <odom_publish_frequency>1</odom_publish_frequency>
        <topic>cmd_vel</topic>
      </plugin>
    </model>
    <model name="depth_camera">
      <pose>4 0 0.5 0 0.0 3.14</pose>
      <link name="link">
        <pose>0.05 0.05 0.05 0 0 0</pose>
        <inertial>
          <mass>0.1</mass>
          <inertia>
            <ixx>0.000166667</ixx>
            <iyy>0.000166667</iyy>
            <izz>0.000166667</izz>
          </inertia>
        </inertial>
        <collision name="collision">
          <geometry>
            <box>
              <size>0.1 0.1 0.1</size>
            </box>
          </geometry>
        </collision>
        <visual name="visual">
          <geometry>
            <box>
              <size>0.1 0.1 0.1</size>
            </box>
          </geometry>
        </visual>
        <sensor name="depth_camera1" type="depth_camera">
          <update_rate>10</update_rate>
          <topic>depth_camera</topic>
          <camera>
            <horizontal_fov>1.5708</horizontal_fov>
            <image>
              <width>640</width>
              <height>480</height>
              <format>R_FLOAT32</format>
            </image>
            <clip>
              <near>0.1</near>
              <far>10.0</far>
            </clip>
          </camera>
          </sensor>
      </link>
      <static>true</static>
    </model>

    <include>
      <pose>0 1 3 0.0 0.0 1.57</pose>
      <uri>
      https://fuel.gazebosim.org/1.0/OpenRobotics/models/Construction Barrel
      </uri>
    </include>

  </world>
</sdf>
