<?xml version="1.0" ?>
<sdf version="1.7">
  <world name="test_world">

  <!-- Define the physics engine -->
    <physics name="1ms" type="ignored">
      <max_step_size>0.001</max_step_size>
      <real_time_factor>1.0</real_time_factor>
    </physics>
    <plugin
      filename="ignition-gazebo-physics-system"
      name="gz::sim::systems::Physics">
    </plugin>
    <plugin
      filename="ignition-gazebo-sensors-system"
      name="gz::sim::systems::Sensors">
      <render_engine>ogre2</render_engine>
    </plugin>
    <plugin
      filename="ignition-gazebo-scene-broadcaster-system"
      name="gz::sim::systems::SceneBroadcaster">
    </plugin>


    <!-- Add a Sun -->
    <light type="directional" name="sun">
      <pose>0 0 10 0 0 0</pose>
    </light>

    <model name="ground_plane">
      <static>true</static>
      <link name="link">
        <collision name="collision">
          <geometry>
            <plane>
              <normal>0 0 1</normal>
            </plane>
          </geometry>
        </collision>
        <visual name="visual">
          <geometry>
            <plane>
              <normal>0 0 1</normal>
              <size>100 100</size>
            </plane>
          </geometry>
          <material>
            <ambient>0.8 0.8 0.8 1</ambient>
            <diffuse>0.8 0.8 0.8 1</diffuse>
            <specular>0.8 0.8 0.8 1</specular>
          </material>
        </visual>
      </link>
    </model>
    
    <model name="box">
      <pose>5 0 1 0 0 0</pose>
      <link name="box_link">
        <inertial>
          <inertia>
            <ixx>1</ixx>
            <ixy>0</ixy>
            <ixz>0</ixz>
            <iyy>1</iyy>
            <iyz>0</iyz>
            <izz>1</izz>
          </inertia>
          <mass>1.0</mass>
        </inertial>
        <collision name="box_collision">
          <geometry>
            <box>
              <size>1 1 1</size>
            </box>
          </geometry>
        </collision>

        <visual name="box_visual">
          <geometry>
            <box>
              <size>1 1 1</size>
            </box>
          </geometry>
          <material>
            <ambient>1 0 0 1</ambient>
            <diffuse>1 0 0 1</diffuse>
            <specular>1 0 0 1</specular>
          </material>
        </visual>
      </link>
    </model>
    
    <model name='rover_4wd' canonical_link='chassis'>
      <pose relative_to='world'>0 0 0 0 0 0</pose>   <!--the pose is relative to the world by default-->
      <frame name="lidar_frame" attached_to='chassis'>
        <pose>0.8 0 0.5 0 0 0</pose>
      </frame>
      <link name='chassis'>
        <pose relative_to='__model__'>0.5 0 0.4 0 0 0</pose>
        <inertial> <!--inertial properties of the link mass, inertia matix-->
          <mass>4.53592</mass>
          <inertia>
            <ixx>0.028064</ixx>
            <ixy>0</ixy>
            <ixz>0</ixz>
            <iyy>0.08226</iyy>
            <iyz>0</iyz>
            <izz>0.10258</izz>
          </inertia>
        </inertial>
        <visual name='visual'>
          <pose>0 0 0.125 1.57 -0 1.57</pose>
          <geometry>
            <mesh>
              <scale>1 1 1</scale>
              <uri>file:///home/jack/rover_workspace/src/roverrobotics_ros2/roverrobotics_description/meshes/flipper_chassis.dae</uri>
            </mesh>
          </geometry>
        </visual>

        <collision name='collision'> <!--todo: describe why we need the collision-->
          <pose>0 0.11 0.125 -1.57159 9.3e-05 -3.14159</pose>
          <geometry>
            <mesh>
              <scale>1 1 1</scale>
              <uri>file:///home/jack/rover_workspace/src/roverrobotics_ros2/roverrobotics_description/meshes/flipper_track.dae</uri>
            </mesh>
          </geometry>
        </collision>
        <sensor name="imu_sensor" type="imu">
          <always_on>1</always_on>
          <update_rate>1</update_rate>
          <visualize>true</visualize>
          <topic>imu</topic>
        </sensor>
        <sensor name='gpu_lidar' type='gpu_lidar'>
          <pose relative_to='lidar_frame'>0 0 0 0 0 0</pose>
          <topic>lidar</topic>
          <update_rate>10</update_rate>
          <ray>
            <scan>
              <horizontal>
                <samples>640</samples>
                <resolution>1</resolution>
                <min_angle>-0.785398</min_angle>  <!-- -π/4 radians -->
                <max_angle>0.785398</max_angle>   <!-- π/4 radians -->
              </horizontal>
              <vertical>
                <samples>480</samples>
                <resolution>1</resolution>
                <min_angle>-0.549778</min_angle>  <!-- -1.099557/2 radians -->
                <max_angle>0.549778</max_angle>   <!-- 1.099557/2 radians -->
              </vertical>
            </scan>
            <range>
              <min>0.08</min>
              <max>10.0</max>
              <resolution>0.01</resolution>
            </range>
          </ray>
          <alwaysOn>1</alwaysOn>
          <visualize>true</visualize>
        </sensor>
      </link>
      <joint name='fl_wheel_to_chassis' type='revolute'>
        <pose relative_to='chassis'>0.1415 0.18 0.125 0 -0 0</pose>
        <parent>chassis</parent>
        <child>fl_wheel_link</child>
        <axis>
          <xyz>0 1 0</xyz>
          <limit>
            <lower>-1e+16</lower>
            <upper>1e+16</upper>
          </limit>
          <dynamics>
            <spring_reference>0</spring_reference>
            <spring_stiffness>0</spring_stiffness>
          </dynamics>
        </axis>
      </joint>
      <link name='fl_wheel_link'>
        <pose relative_to='fl_wheel_to_chassis'>0 0 0 0 -0 0</pose>
        <inertial>
          <pose>0 0 0 0 -0 0</pose>
          <mass>1.25</mass>
          <inertia>
            <ixx>0.005645</ixx>
            <ixy>0</ixy>
            <ixz>0</ixz>
            <iyy>0.01008</iyy>
            <iyz>0</iyz>
            <izz>0.005645</izz>
          </inertia>
        </inertial>
        <collision name='fl_wheel_link_collision'>
          <pose>0 0 0 1.57 -0 0</pose>
          <geometry>
            <mesh>
              <scale>1 1 1</scale>
              <uri>file:///home/jack/rover_workspace/src/roverrobotics_ros2/roverrobotics_description/meshes/pro_tire.dae</uri>
            </mesh>
          </geometry>
        </collision>
        <visual name='fl_wheel_link_visual'>
          <pose>0 0 0 1.57 -0 0</pose>
          <geometry>
            <mesh>
              <scale>1 1 1</scale>
              <uri>file:///home/jack/rover_workspace/src/roverrobotics_ros2/roverrobotics_description/meshes/pro_tire.dae</uri>
            </mesh>
          </geometry>
        </visual>
      </link>
      <joint name='fr_wheel_to_chassis' type='revolute'>
        <pose relative_to='chassis'>0.1415 -0.18 0.125 0 -0 0</pose>
        <parent>chassis</parent>
        <child>fr_wheel_link</child>
        <axis>
          <xyz>0 1 0</xyz>
          <limit>
            <lower>-1e+16</lower>
            <upper>1e+16</upper>
          </limit>
          <dynamics>
            <spring_reference>0</spring_reference>
            <spring_stiffness>0</spring_stiffness>
          </dynamics>
        </axis>
      </joint>
      <link name='fr_wheel_link'>
        <pose relative_to='fr_wheel_to_chassis'>0 0 0 0 -0 0</pose>
        <inertial>
          <pose>0 0 0 0 -0 0</pose>
          <mass>1.25</mass>
          <inertia>
            <ixx>0.005645</ixx>
            <ixy>0</ixy>
            <ixz>0</ixz>
            <iyy>0.01008</iyy>
            <iyz>0</iyz>
            <izz>0.005645</izz>
          </inertia>
        </inertial>
        <collision name='fr_wheel_link_collision'>
          <pose>0 0 0 -1.57 0 0</pose>
          <geometry>
            <mesh>
              <scale>1 1 1</scale>
              <uri>file:///home/jack/rover_workspace/src/roverrobotics_ros2/roverrobotics_description/meshes/pro_tire.dae</uri>
            </mesh>
          </geometry>
        </collision>
        <visual name='fr_wheel_link_visual'>
          <pose>0 0 0 -1.57 0 0</pose>
          <geometry>
            <mesh>
              <scale>1 1 1</scale>
              <uri>file:///home/jack/rover_workspace/src/roverrobotics_ros2/roverrobotics_description/meshes/pro_tire.dae</uri>
            </mesh>
          </geometry>
        </visual>
      </link>
      <joint name='rl_wheel_to_chassis' type='revolute'>
        <pose relative_to='chassis'>-0.145 0.18 0.125 0 -0 0</pose>
        <parent>chassis</parent>
        <child>rl_wheel_link</child>
        <axis>
          <xyz>0 1 0</xyz>
          <limit>
            <lower>-1e+16</lower>
            <upper>1e+16</upper>
          </limit>
          <dynamics>
            <spring_reference>0</spring_reference>
            <spring_stiffness>0</spring_stiffness>
          </dynamics>
        </axis>
      </joint>
      <link name='rl_wheel_link'>
        <pose relative_to='rl_wheel_to_chassis'>0 0 0 0 -0 0</pose>
        <inertial>
          <pose>0 0 0 0 -0 0</pose>
          <mass>1.25</mass>
          <inertia>
            <ixx>0.005645</ixx>
            <ixy>0</ixy>
            <ixz>0</ixz>
            <iyy>0.01008</iyy>
            <iyz>0</iyz>
            <izz>0.005645</izz>
          </inertia>
        </inertial>
        <collision name='rl_wheel_link_collision'>
          <pose>0 0 0 -1.57 -0 3.1415</pose>
          <geometry>
            <mesh>
              <scale>1 1 1</scale>
              <uri>file:///home/jack/rover_workspace/src/roverrobotics_ros2/roverrobotics_description/meshes/pro_tire.dae</uri>
            </mesh>
          </geometry>
        </collision>
        <visual name='rl_wheel_link_visual'>
          <pose>0 0 0 -1.57 -0 3.1415</pose>
          <geometry>
            <mesh>
              <scale>1 1 1</scale>
              <uri>file:///home/jack/rover_workspace/src/roverrobotics_ros2/roverrobotics_description/meshes/pro_tire.dae</uri>
            </mesh>
          </geometry>
        </visual>
      </link>
      <joint name='rr_wheel_to_chassis' type='revolute'>
        <pose relative_to='chassis'>-0.145 -0.18 0.125 0 -0 0</pose>
        <parent>chassis</parent>
        <child>rr_wheel_link</child>
        <axis>
          <xyz>0 1 0</xyz>
          <limit>
            <lower>-1e+16</lower>
            <upper>1e+16</upper>
          </limit>
          <dynamics>
            <spring_reference>0</spring_reference>
            <spring_stiffness>0</spring_stiffness>
          </dynamics>
        </axis>
      </joint>
      <link name='rr_wheel_link'>
        <pose relative_to='rr_wheel_to_chassis'>0 0 0 0 -0 0</pose>
        <inertial>
          <pose>0 0 0 0 -0 0</pose>
          <mass>1.25</mass>
          <inertia>
            <ixx>0.005645</ixx>
            <ixy>0</ixy>
            <ixz>0</ixz>
            <iyy>0.01008</iyy>
            <iyz>0</iyz>
            <izz>0.005645</izz>
          </inertia>
        </inertial>
        <collision name='rr_wheel_link_collision'>
          <pose>0 0 0 1.57 0 3.1415</pose>
          <geometry>
            <mesh>
              <scale>1 1 1</scale>
              <uri>file:///home/jack/rover_workspace/src/roverrobotics_ros2/roverrobotics_description/meshes/pro_tire.dae</uri>
            </mesh>
          </geometry>
        </collision>
        <visual name='rr_wheel_link_visual'>
          <pose>0 0 0 1.57 0 3.1415</pose>
          <geometry>
            <mesh>
              <scale>1 1 1</scale>
              <uri>file:///home/jack/rover_workspace/src/roverrobotics_ros2/roverrobotics_description/meshes/pro_tire.dae</uri>
            </mesh>
          </geometry>
        </visual>
      </link>


      <!--diff drive plugin-->
      <plugin name='ignition::gazebo::systems::DiffDrive' filename='ignition-gazebo-diff-drive-system'>
        <num_wheel_pairs>2</num_wheel_pairs>
        <left_joint>rl_wheel_to_chassis</left_joint>
        <left_joint>fl_wheel_to_chassis</left_joint>
        <right_joint>rr_wheel_to_chassis</right_joint>
        <right_joint>fr_wheel_to_chassis</right_joint>
        <wheel_separation>0.24</wheel_separation>
        <wheel_radius>0.122</wheel_radius>
        <max_linear_acceleration>5</max_linear_acceleration>
        <min_linear_acceleration>-5</min_linear_acceleration>
        <max_angular_acceleration>4</max_angular_acceleration>
        <min_angular_acceleration>-4</min_angular_acceleration>
        <frame_id>odom</frame_id>
        <child_frame_id>chassis</child_frame_id>
        <topic>/cmd_vel</topic>
        <odom_topic>/odometry/wheels</odom_topic>
        <tf_topic>/tf_gazebo</tf_topic>
      </plugin>
      <plugin name='ignition::gazebo::systems::JointStatePublisher' filename='ignition-gazebo-joint-state-publisher-system'>
        <topic>/joint_states</topic>
      </plugin>
      
      <frame name="depth_frame" attached_to='chassis'>
        <pose>0.8 0 0.5 0 0 0</pose>
      </frame>
      
    </model>

    <!-- Include your robot model -->
    <!--
    <include>
      <uri>file://home/jack/src/rover_zero/gazebo/sdf/bakNew/rover_4wd_depth_2.sdf</uri>

    </include>
    -->
  </world>
</sdf>
